<?xml version="1.0" encoding="utf-8"?><testsuites><testsuite errors="0" failures="0" hostname="alberto-XPS-13-9370" name="pytest" skipped="0" tests="6" time="4.009" timestamp="2020-09-25T15:19:15.207944"><testcase classname="tests.test_main" file="tests/test_main.py" line="11" name="test_get_data" time="3.157"><system-out>ERROR: Unable to locate credentials
</system-out></testcase><testcase classname="tests.test_main" file="tests/test_main.py" line="18" name="test_get_prefix_data" time="0.001"></testcase><testcase classname="tests.test_main" file="tests/test_main.py" line="25" name="test_enrich_data_with_known_prefix" time="0.329"></testcase><testcase classname="tests.test_main" file="tests/test_main.py" line="32" name="test_enrich_data_with_unknown_prefix" time="0.001"></testcase><testcase classname="tests.test_main" file="tests/test_main.py" line="38" name="test_persist_dynamodb" time="0.011"></testcase><testcase classname="tests.test_main" file="tests/test_main.py" line="46" name="test_persist_s3" time="0.447"></testcase></testsuite></testsuites>